Workbook
Name N_EXPERTS: 'Expert Panel'!$B$12
Name CVI_PASS: 'Expert Panel'!$B$13
Name CVI_BORDER: 'Expert Panel'!$B$14

Sheet Instructions
A1: AwadhVaani — CVI Analysis Spreadsheet
A2: Content Validity Index analysis for the Awadhi language-learning app
A4: THE 4-POINT RELEVANCE SCALE
A5: 1 | B5: Not relevant — does not belong in an Awadhi learning curriculum
A6: 2 | B6: Somewhat relevant — peripheral, could be omitted
A7: 3 | B7: Quite relevant — should be included
A8: 4 | B8: Highly relevant — essential to the curriculum
A10: HOW THE METRICS ARE COMPUTED
A11: I-CVI | B11: Item-level CVI = (# experts rating ≥3) / (total # experts)
A12: S-CVI/Ave | B12: Scale-level CVI (average) = mean of all I-CVI values
A13: S-CVI/UA | B13: Universal Agreement CVI = (# items rated ≥3 by ALL experts) / total items
A14: Mean | B14: Average of all expert ratings for the item (informational, not part of CVI)
A15: SD | B15: Standard deviation of expert ratings — high SD = experts disagree
A16: Pc | B16: Chance agreement: COMBIN(N,A) × 0.5^N · where N=experts, A=# rating ≥3
A17: κ* (Kappa) | B17: Modified Kappa = (I-CVI − Pc) / (1 − Pc) · corrects CVI for chance agreement
A19: ACCEPTANCE THRESHOLDS
A20: I-CVI ≥ 0.78 | B20: PASS — for a panel of 6–10 experts (Lynn, 1986)
A21: I-CVI ≥ 0.83 | B21: PASS — for a panel of 3–5 experts (stricter, smaller N)
A22: I-CVI 0.60–0.78 | B22: BORDERLINE — needs revision or expert discussion
A23: I-CVI < 0.60 | B23: FAIL — revise or drop from curriculum
A24: S-CVI/Ave ≥ 0.90 | B24: Excellent — scale is content-valid
A25: S-CVI/Ave 0.80–0.89 | B25: Adequate — minor revisions needed
A26: S-CVI/UA ≥ 0.80 | B26: Strict universal-agreement target
A27: κ* > 0.74 | B27: Excellent agreement (gold standard for publication)
A28: κ* 0.60–0.74 | B28: Good
A29: κ* < 0.40 | B29: Poor — revise item
A31: HOW TO USE THIS WORKBOOK
A32: Step 1 | B32: On the "Expert Panel" tab, fill in details for E1–E7 (name, affiliation, background, experience).
A33: Step 2 | B33: On the "Items & Ratings" tab, enter each expert's rating (1–4) in their column (H–N) for every item they evaluated.
A34: Step 3 | B34: I-CVI, Mean, SD, Pc, κ*, and Status auto-compute as ratings are entered.
A35: Step 4 | B35: The "Summary" tab updates automatically: S-CVI/Ave, S-CVI/UA, mean κ*, pass/borderline/fail counts, per-type breakdown.
A36: Step 5 | B36: Items marked FAIL or BORDERLINE go in your revision queue. Item-level κ* < 0.40 should be revised or dropped.
A37: Step 6 | B37: Use the "Summary" numbers as the headline result in your validity report.
A39: COLOR LEGEND (in the Items tab)
A40: PASS | B40: I-CVI ≥ 0.78 — item is content-valid
A41: BORDERLINE | B41: I-CVI 0.60–0.78 — needs discussion
A42: FAIL | B42: I-CVI < 0.60 — revise or drop
A43: Awaiting | B43: No expert ratings entered yet

Sheet Items & Ratings
A1: Item ID | B1: Type | C1: Awadhi | D1: Roman | E1: English | F1: Category | G1: Context | H1: E1 | I1: E2 | J1: E3 | K1: E4 | L1: E5 | M1: E6 | N1: E7 | O1: # ≥3 | P1: I-CVI | Q1: Mean | R1: SD | S1: Pc | T1: κ* | U1: Status
A2: V001 | B2: Vocabulary | C2: घर | D2: Ghar | E2: House / Home | F2: Home | O2: =COUNTIF(H2:N2,">=3") | P2: =IF(COUNT(H2:N2)=0,"",COUNTIF(H2:N2,">=3")/COUNT(H2:N2)) | Q2: =IF(COUNT(H2:N2)=0,"",AVERAGE(H2:N2)) | R2: =IF(COUNT(H2:N2)<2,"",STDEV(H2:N2)) | S2: =IF(COUNT(H2:N2)=0,"",COMBIN(COUNT(H2:N2),COUNTIF(H2:N2,">=3"))*0.5^COUNT(H2:N2)) | T2: =IFERROR(IF(P2="","",(P2-S2)/(1-S2)),"") | U2: =IF(P2="","Awaiting",IF(P2>=CVI_PASS,"PASS",IF(P2>=CVI_BORDER,"BORDERLINE","FAIL")))
A3: V002 | B3: Vocabulary | C3: कमरा | D3: Kamra | E3: Room | F3: Home | O3: =COUNTIF(H3:N3,">=3") | P3: =IF(COUNT(H3:N3)=0,"",COUNTIF(H3:N3,">=3")/COUNT(H3:N3)) | Q3: =IF(COUNT(H3:N3)=0,"",AVERAGE(H3:N3)) | R3: =IF(COUNT(H3:N3)<2,"",STDEV(H3:N3)) | S3: =IF(COUNT(H3:N3)=0,"",COMBIN(COUNT(H3:N3),COUNTIF(H3:N3,">=3"))*0.5^COUNT(H3:N3)) | T3: =IFERROR(IF(P3="","",(P3-S3)/(1-S3)),"") | U3: =IF(P3="","Awaiting",IF(P3>=CVI_PASS,"PASS",IF(P3>=CVI_BORDER,"BORDERLINE","FAIL")))
A4: V003 | B4: Vocabulary | C4: झाडू | D4: Jhaadu | E4: Broom | F4: Home | O4: =COUNTIF(H4:N4,">=3") | P4: =IF(COUNT(H4:N4)=0,"",COUNTIF(H4:N4,">=3")/COUNT(H4:N4)) | Q4: =IF(COUNT(H4:N4)=0,"",AVERAGE(H4:N4)) | R4: =IF(COUNT(H4:N4)<2,"",STDEV(H4:N4)) | S4: =IF(COUNT(H4:N4)=0,"",COMBIN(COUNT(H4:N4),COUNTIF(H4:N4,">=3"))*0.5^COUNT(H4:N4)) | T4: =IFERROR(IF(P4="","",(P4-S4)/(1-S4)),"") | U4: =IF(P4="","Awaiting",IF(P4>=CVI_PASS,"PASS",IF(P4>=CVI_BORDER,"BORDERLINE","FAIL")))
A5: V004 | B5: Vocabulary | C5: टैंक | D5: Tank | E5: Tank / Reservoir | F5: Home | O5: =COUNTIF(H5:N5,">=3") | P5: =IF(COUNT(H5:N5)=0,"",COUNTIF(H5:N5,">=3")/COUNT(H5:N5)) | Q5: =IF(COUNT(H5:N5)=0,"",AVERAGE(H5:N5)) | R5: =IF(COUNT(H5:N5)<2,"",STDEV(H5:N5)) | S5: =IF(COUNT(H5:N5)=0,"",COMBIN(COUNT(H5:N5),COUNTIF(H5:N5,">=3"))*0.5^COUNT(H5:N5)) | T5: =IFERROR(IF(P5="","",(P5-S5)/(1-S5)),"") | U5: =IF(P5="","Awaiting",IF(P5>=CVI_PASS,"PASS",IF(P5>=CVI_BORDER,"BORDERLINE","FAIL")))
A6: V005 | B6: Vocabulary | C6: रस्सी | D6: Rassi | E6: Rope | F6: Home | O6: =COUNTIF(H6:N6,">=3") | P6: =IF(COUNT(H6:N6)=0,"",COUNTIF(H6:N6,">=3")/COUNT(H6:N6)) | Q6: =IF(COUNT(H6:N6)=0,"",AVERAGE(H6:N6)) | R6: =IF(COUNT(H6:N6)<2,"",STDEV(H6:N6)) | S6: =IF(COUNT(H6:N6)=0,"",COMBIN(COUNT(H6:N6),COUNTIF(H6:N6,">=3"))*0.5^COUNT(H6:N6)) | T6: =IFERROR(IF(P6="","",(P6-S6)/(1-S6)),"") | U6: =IF(P6="","Awaiting",IF(P6>=CVI_PASS,"PASS",IF(P6>=CVI_BORDER,"BORDERLINE","FAIL")))
A7: V006 | B7: Vocabulary | C7: कुण्डा | D7: Kunda | E7: Latch / Lock | F7: Home | O7: =COUNTIF(H7:N7,">=3") | P7: =IF(COUNT(H7:N7)=0,"",COUNTIF(H7:N7,">=3")/COUNT(H7:N7)) | Q7: =IF(COUNT(H7:N7)=0,"",AVERAGE(H7:N7)) | R7: =IF(COUNT(H7:N7)<2,"",STDEV(H7:N7)) | S7: =IF(COUNT(H7:N7)=0,"",COMBIN(COUNT(H7:N7),COUNTIF(H7:N7,">=3"))*0.5^COUNT(H7:N7)) | T7: =IFERROR(IF(P7="","",(P7-S7)/(1-S7)),"") | U7: =IF(P7="","Awaiting",IF(P7>=CVI_PASS,"PASS",IF(P7>=CVI_BORDER,"BORDERLINE","FAIL")))
A8: V007 | B8: Vocabulary | C8: पानी | D8: Paani | E8: Water | F8: Home | O8: =COUNTIF(H8:N8,">=3") | P8: =IF(COUNT(H8:N8)=0,"",COUNTIF(H8:N8,">=3")/COUNT(H8:N8)) | Q8: =IF(COUNT(H8:N8)=0,"",AVERAGE(H8:N8)) | R8: =IF(COUNT(H8:N8)<2,"",STDEV(H8:N8)) | S8: =IF(COUNT(H8:N8)=0,"",COMBIN(COUNT(H8:N8),COUNTIF(H8:N8,">=3"))*0.5^COUNT(H8:N8)) | T8: =IFERROR(IF(P8="","",(P8-S8)/(1-S8)),"") | U8: =IF(P8="","Awaiting",IF(P8>=CVI_PASS,"PASS",IF(P8>=CVI_BORDER,"BORDERLINE","FAIL")))
A9: V008 | B9: Vocabulary | C9: भाय | D9: Bhaay | E9: Brother | F9: Family | O9: =COUNTIF(H9:N9,">=3") | P9: =IF(COUNT(H9:N9)=0,"",COUNTIF(H9:N9,">=3")/COUNT(H9:N9)) | Q9: =IF(COUNT(H9:N9)=0,"",AVERAGE(H9:N9)) | R9: =IF(COUNT(H9:N9)<2,"",STDEV(H9:N9)) | S9: =IF(COUNT(H9:N9)=0,"",COMBIN(COUNT(H9:N9),COUNTIF(H9:N9,">=3"))*0.5^COUNT(H9:N9)) | T9: =IFERROR(IF(P9="","",(P9-S9)/(1-S9)),"") | U9: =IF(P9="","Awaiting",IF(P9>=CVI_PASS,"PASS",IF(P9>=CVI_BORDER,"BORDERLINE","FAIL")))
A10: V009 | B10: Vocabulary | C10: बहिन | D10: Bahin | E10: Sister | F10: Family | O10: =COUNTIF(H10:N10,">=3") | P10: =IF(COUNT(H10:N10)=0,"",COUNTIF(H10:N10,">=3")/COUNT(H10:N10)) | Q10: =IF(COUNT(H10:N10)=0,"",AVERAGE(H10:N10)) | R10: =IF(COUNT(H10:N10)<2,"",STDEV(H10:N10)) | S10: =IF(COUNT(H10:N10)=0,"",COMBIN(COUNT(H10:N10),COUNTIF(H10:N10,">=3"))*0.5^COUNT(H10:N10)) | T10: =IFERROR(IF(P10="","",(P10-S10)/(1-S10)),"") | U10: =IF(P10="","Awaiting",IF(P10>=CVI_PASS,"PASS",IF(P10>=CVI_BORDER,"BORDERLINE","FAIL")))
A11: V010 | B11: Vocabulary | C11: अम्मा | D11: Amma | E11: Mother | F11: Family | O11: =COUNTIF(H11:N11,">=3") | P11: =IF(COUNT(H11:N11)=0,"",COUNTIF(H11:N11,">=3")/COUNT(H11:N11)) | Q11: =IF(COUNT(H11:N11)=0,"",AVERAGE(H11:N11)) | R11: =IF(COUNT(H11:N11)<2,"",STDEV(H11:N11)) | S11: =IF(COUNT(H11:N11)=0,"",COMBIN(COUNT(H11:N11),COUNTIF(H11:N11,">=3"))*0.5^COUNT(H11:N11)) | T11: =IFERROR(IF(P11="","",(P11-S11)/(1-S11)),"") | U11: =IF(P11="","Awaiting",IF(P11>=CVI_PASS,"PASS",IF(P11>=CVI_BORDER,"BORDERLINE","FAIL")))
A12: V011 | B12: Vocabulary | C12: महतारी | D12: Mahtari | E12: Mother (dialectal) | F12: Family | O12: =COUNTIF(H12:N12,">=3") | P12: =IF(COUNT(H12:N12)=0,"",COUNTIF(H12:N12,">=3")/COUNT(H12:N12)) | Q12: =IF(COUNT(H12:N12)=0,"",AVERAGE(H12:N12)) | R12: =IF(COUNT(H12:N12)<2,"",STDEV(H12:N12)) | S12: =IF(COUNT(H12:N12)=0,"",COMBIN(COUNT(H12:N12),COUNTIF(H12:N12,">=3"))*0.5^COUNT(H12:N12)) | T12: =IFERROR(IF(P12="","",(P12-S12)/(1-S12)),"") | U12: =IF(P12="","Awaiting",IF(P12>=CVI_PASS,"PASS",IF(P12>=CVI_BORDER,"BORDERLINE","FAIL")))
A13: V012 | B13: Vocabulary | C13: बाप | D13: Baap | E13: Father | F13: Family | O13: =COUNTIF(H13:N13,">=3") | P13: =IF(COUNT(H13:N13)=0,"",COUNTIF(H13:N13,">=3")/COUNT(H13:N13)) | Q13: =IF(COUNT(H13:N13)=0,"",AVERAGE(H13:N13)) | R13: =IF(COUNT(H13:N13)<2,"",STDEV(H13:N13)) | S13: =IF(COUNT(H13:N13)=0,"",COMBIN(COUNT(H13:N13),COUNTIF(H13:N13,">=3"))*0.5^COUNT(H13:N13)) | T13: =IFERROR(IF(P13="","",(P13-S13)/(1-S13)),"") | U13: =IF(P13="","Awaiting",IF(P13>=CVI_PASS,"PASS",IF(P13>=CVI_BORDER,"BORDERLINE","FAIL")))
... A65: V064 | B65: Vocabulary | C65: तेरहवीं | D65: Terhaveen | E65: 13th Day Death Ritual | F65: Cultural | O65: =COUNTIF(H65:N65,">=3") | P65: =IF(COUNT(H65:N65)=0,"",COUNTIF(H65:N65,">=3")/COUNT(H65:N65)) | Q65: =IF(COUNT(H65:N65)=0,"",AVERAGE(H65:N65)) | R65: =IF(COUNT(H65:N65)<2,"",STDEV(H65:N65)) | S65: =IF(COUNT(H65:N65)=0,"",COMBIN(COUNT(H65:N65),COUNTIF(H65:N65,">=3"))*0.5^COUNT(H65:N65)) | T65: =IFERROR(IF(P65="","",(P65-S65)/(1-S65)),"") | U65: =IF(P65="","Awaiting",IF(P65>=CVI_PASS,"PASS",IF(P65>=CVI_BORDER,"BORDERLINE","FAIL")))
A66: L001 | B66: Lesson Sentence | C66: प्रणाम | D66: Pranaam | E66: Greetings / Salutation | F66: Greetings & Basics | G66: Unit 1: Greetings & Basics / Pranaam — Greetings | O66: =COUNTIF(H66:N66,">=3") | P66: =IF(COUNT(H66:N66)=0,"",COUNTIF(H66:N66,">=3")/COUNT(H66:N66)) | Q66: =IF(COUNT(H66:N66)=0,"",AVERAGE(H66:N66)) | R66: =IF(COUNT(H66:N66)<2,"",STDEV(H66:N66)) | S66: =IF(COUNT(H66:N66)=0,"",COMBIN(COUNT(H66:N66),COUNTIF(H66:N66,">=3"))*0.5^COUNT(H66:N66)) | T66: =IFERROR(IF(P66="","",(P66-S66)/(1-S66)),"") | U66: =IF(P66="","Awaiting",IF(P66>=CVI_PASS,"PASS",IF(P66>=CVI_BORDER,"BORDERLINE","FAIL")))
A67: L002 | B67: Lesson Sentence | C67: कइसे अहा? | D67: Kaise aha? | E67: How are you? | F67: Greetings & Basics | G67: Unit 1: Greetings & Basics / Pranaam — Greetings | O67: =COUNTIF(H67:N67,">=3") | P67: =IF(COUNT(H67:N67)=0,"",COUNTIF(H67:N67,">=3")/COUNT(H67:N67)) | Q67: =IF(COUNT(H67:N67)=0,"",AVERAGE(H67:N67)) | R67: =IF(COUNT(H67:N67)<2,"",STDEV(H67:N67)) | S67: =IF(COUNT(H67:N67)=0,"",COMBIN(COUNT(H67:N67),COUNTIF(H67:N67,">=3"))*0.5^COUNT(H67:N67)) | T67: =IFERROR(IF(P67="","",(P67-S67)/(1-S67)),"") | U67: =IF(P67="","Awaiting",IF(P67>=CVI_PASS,"PASS",IF(P67>=CVI_BORDER,"BORDERLINE","FAIL")))
A68: L003 | B68: Lesson Sentence | C68: हम ठीक अही। | D68: Hum theek ahi. | E68: I am fine. | F68: Greetings & Basics | G68: Unit 1: Greetings & Basics / Pranaam — Greetings | O68: =COUNTIF(H68:N68,">=3") | P68: =IF(COUNT(H68:N68)=0,"",COUNTIF(H68:N68,">=3")/COUNT(H68:N68)) | Q68: =IF(COUNT(H68:N68)=0,"",AVERAGE(H68:N68)) | R68: =IF(COUNT(H68:N68)<2,"",STDEV(H68:N68)) | S68: =IF(COUNT(H68:N68)=0,"",COMBIN(COUNT(H68:N68),COUNTIF(H68:N68,">=3"))*0.5^COUNT(H68:N68)) | T68: =IFERROR(IF(P68="","",(P68-S68)/(1-S68)),"") | U68: =IF(P68="","Awaiting",IF(P68>=CVI_PASS,"PASS",IF(P68>=CVI_BORDER,"BORDERLINE","FAIL")))
A69: L004 | B69: Lesson Sentence | C69: तोहार नाम का अहय? | D69: Tohar naam ka ahay? | E69: What is your name? | F69: Greetings & Basics | G69: Unit 1: Greetings & Basics / Pranaam — Greetings | O69: =COUNTIF(H69:N69,">=3") | P69: =IF(COUNT(H69:N69)=0,"",COUNTIF(H69:N69,">=3")/COUNT(H69:N69)) | Q69: =IF(COUNT(H69:N69)=0,"",AVERAGE(H69:N69)) | R69: =IF(COUNT(H69:N69)<2,"",STDEV(H69:N69)) | S69: =IF(COUNT(H69:N69)=0,"",COMBIN(COUNT(H69:N69),COUNTIF(H69:N69,">=3"))*0.5^COUNT(H69:N69)) | T69: =IFERROR(IF(P69="","",(P69-S69)/(1-S69)),"") | U69: =IF(P69="","Awaiting",IF(P69>=CVI_PASS,"PASS",IF(P69>=CVI_BORDER,"BORDERLINE","FAIL")))
A70: L005 | B70: Lesson Sentence | C70: हम राधा अही। | D70: Hum Radha ahi. | E70: I am Radha. | F70: Greetings & Basics | G70: Unit 1: Greetings & Basics / Mora Naam — Introductions | O70: =COUNTIF(H70:N70,">=3") | P70: =IF(COUNT(H70:N70)=0,"",COUNTIF(H70:N70,">=3")/COUNT(H70:N70)) | Q70: =IF(COUNT(H70:N70)=0,"",AVERAGE(H70:N70)) | R70: =IF(COUNT(H70:N70)<2,"",STDEV(H70:N70)) | S70: =IF(COUNT(H70:N70)=0,"",COMBIN(COUNT(H70:N70),COUNTIF(H70:N70,">=3"))*0.5^COUNT(H70:N70)) | T70: =IFERROR(IF(P70="","",(P70-S70)/(1-S70)),"") | U70: =IF(P70="","Awaiting",IF(P70>=CVI_PASS,"PASS",IF(P70>=CVI_BORDER,"BORDERLINE","FAIL")))
A71: L006 | B71: Lesson Sentence | C71: हम हियाँ तुहका देखय आवा रहिन। | D71: Hum hiyaan tuhka dekhay aava rahin. | E71: I came here to see you. | F71: Greetings & Basics | G71: Unit 1: Greetings & Basics / Mora Naam — Introductions | O71: =COUNTIF(H71:N71,">=3") | P71: =IF(COUNT(H71:N71)=0,"",COUNTIF(H71:N71,">=3")/COUNT(H71:N71)) | Q71: =IF(COUNT(H71:N71)=0,"",AVERAGE(H71:N71)) | R71: =IF(COUNT(H71:N71)<2,"",STDEV(H71:N71)) | S71: =IF(COUNT(H71:N71)=0,"",COMBIN(COUNT(H71:N71),COUNTIF(H71:N71,">=3"))*0.5^COUNT(H71:N71)) | T71: =IFERROR(IF(P71="","",(P71-S71)/(1-S71)),"") | U71: =IF(P71="","Awaiting",IF(P71>=CVI_PASS,"PASS",IF(P71>=CVI_BORDER,"BORDERLINE","FAIL")))
A72: L007 | B72: Lesson Sentence | C72: कृपया जा। | D72: Kripaya ja. | E72: Please go. | F72: Greetings & Basics | G72: Unit 1: Greetings & Basics / Mora Naam — Introductions | O72: =COUNTIF(H72:N72,">=3") | P72: =IF(COUNT(H72:N72)=0,"",COUNTIF(H72:N72,">=3")/COUNT(H72:N72)) | Q72: =IF(COUNT(H72:N72)=0,"",AVERAGE(H72:N72)) | R72: =IF(COUNT(H72:N72)<2,"",STDEV(H72:N72)) | S72: =IF(COUNT(H72:N72)=0,"",COMBIN(COUNT(H72:N72),COUNTIF(H72:N72,">=3"))*0.5^COUNT(H72:N72)) | T72: =IFERROR(IF(P72="","",(P72-S72)/(1-S72)),"") | U72: =IF(P72="","Awaiting",IF(P72>=CVI_PASS,"PASS",IF(P72>=CVI_BORDER,"BORDERLINE","FAIL")))
A73: L008 | B73: Lesson Sentence | C73: चला जा। | D73: Chala ja. | E73: Let's go. | F73: Greetings & Basics | G73: Unit 1: Greetings & Basics / Mora Naam — Introductions | O73: =COUNTIF(H73:N73,">=3") | P73: =IF(COUNT(H73:N73)=0,"",COUNTIF(H73:N73,">=3")/COUNT(H73:N73)) | Q73: =IF(COUNT(H73:N73)=0,"",AVERAGE(H73:N73)) | R73: =IF(COUNT(H73:N73)<2,"",STDEV(H73:N73)) | S73: =IF(COUNT(H73:N73)=0,"",COMBIN(COUNT(H73:N73),COUNTIF(H73:N73,">=3"))*0.5^COUNT(H73:N73)) | T73: =IFERROR(IF(P73="","",(P73-S73)/(1-S73)),"") | U73: =IF(P73="","Awaiting",IF(P73>=CVI_PASS,"PASS",IF(P73>=CVI_BORDER,"BORDERLINE","FAIL")))
A74: L009 | B74: Lesson Sentence | C74: हाँ | D74: Haan | E74: Yes | F74: Greetings & Basics | G74: Unit 1: Greetings & Basics / Basic Expressions | O74: =COUNTIF(H74:N74,">=3") | P74: =IF(COUNT(H74:N74)=0,"",COUNTIF(H74:N74,">=3")/COUNT(H74:N74)) | Q74: =IF(COUNT(H74:N74)=0,"",AVERAGE(H74:N74)) | R74: =IF(COUNT(H74:N74)<2,"",STDEV(H74:N74)) | S74: =IF(COUNT(H74:N74)=0,"",COMBIN(COUNT(H74:N74),COUNTIF(H74:N74,">=3"))*0.5^COUNT(H74:N74)) | T74: =IFERROR(IF(P74="","",(P74-S74)/(1-S74)),"") | U74: =IF(P74="","Awaiting",IF(P74>=CVI_PASS,"PASS",IF(P74>=CVI_BORDER,"BORDERLINE","FAIL")))
A75: L010 | B75: Lesson Sentence | C75: नाहीं | D75: Naahin | E75: No | F75: Greetings & Basics | G75: Unit 1: Greetings & Basics / Basic Expressions | O75: =COUNTIF(H75:N75,">=3") | P75: =IF(COUNT(H75:N75)=0,"",COUNTIF(H75:N75,">=3")/COUNT(H75:N75)) | Q75: =IF(COUNT(H75:N75)=0,"",AVERAGE(H75:N75)) | R75: =IF(COUNT(H75:N75)<2,"",STDEV(H75:N75)) | S75: =IF(COUNT(H75:N75)=0,"",COMBIN(COUNT(H75:N75),COUNTIF(H75:N75,">=3"))*0.5^COUNT(H75:N75)) | T75: =IFERROR(IF(P75="","",(P75-S75)/(1-S75)),"") | U75: =IF(P75="","Awaiting",IF(P75>=CVI_PASS,"PASS",IF(P75>=CVI_BORDER,"BORDERLINE","FAIL")))
A76: L011 | B76: Lesson Sentence | C76: धन्यवाद | D76: Dhanyavaad | E76: Thank you | F76: Greetings & Basics | G76: Unit 1: Greetings & Basics / Basic Expressions | O76: =COUNTIF(H76:N76,">=3") | P76: =IF(COUNT(H76:N76)=0,"",COUNTIF(H76:N76,">=3")/COUNT(H76:N76)) | Q76: =IF(COUNT(H76:N76)=0,"",AVERAGE(H76:N76)) | R76: =IF(COUNT(H76:N76)<2,"",STDEV(H76:N76)) | S76: =IF(COUNT(H76:N76)=0,"",COMBIN(COUNT(H76:N76),COUNTIF(H76:N76,">=3"))*0.5^COUNT(H76:N76)) | T76: =IFERROR(IF(P76="","",(P76-S76)/(1-S76)),"") | U76: =IF(P76="","Awaiting",IF(P76>=CVI_PASS,"PASS",IF(P76>=CVI_BORDER,"BORDERLINE","FAIL")))
A77: L012 | B77: Lesson Sentence | C77: वे हमका आशीर्वाद देहें। | D77: Ve humka aashirvaad dehen. | E77: They blessed me. | F77: Greetings & Basics | G77: Unit 1: Greetings & Basics / Basic Expressions | O77: =COUNTIF(H77:N77,">=3") | P77: =IF(COUNT(H77:N77)=0,"",COUNTIF(H77:N77,">=3")/COUNT(H77:N77)) | Q77: =IF(COUNT(H77:N77)=0,"",AVERAGE(H77:N77)) | R77: =IF(COUNT(H77:N77)<2,"",STDEV(H77:N77)) | S77: =IF(COUNT(H77:N77)=0,"",COMBIN(COUNT(H77:N77),COUNTIF(H77:N77,">=3"))*0.5^COUNT(H77:N77)) | T77: =IFERROR(IF(P77="","",(P77-S77)/(1-S77)),"") | U77: =IF(P77="","Awaiting",IF(P77>=CVI_PASS,"PASS",IF(P77>=CVI_BORDER,"BORDERLINE","FAIL")))
... A149: Q025 | B149: Quiz Item | C149: कलेवा | D149: Kalewa | E149: Morning Meal / Breakfast | F149: Vocabulary / Translate the Word | G149: Prompt: What does 'Kalewa' mean? | Options: Evening Meal / Morning Meal / Breakfast / Festive Feast / Midnight Snack | O149: =COUNTIF(H149:N149,">=3") | P149: =IF(COUNT(H149:N149)=0,"",COUNTIF(H149:N149,">=3")/COUNT(H149:N149)) | Q149: =IF(COUNT(H149:N149)=0,"",AVERAGE(H149:N149)) | R149: =IF(COUNT(H149:N149)<2,"",STDEV(H149:N149)) | S149: =IF(COUNT(H149:N149)=0,"",COMBIN(COUNT(H149:N149),COUNTIF(H149:N149,">=3"))*0.5^COUNT(H149:N149)) | T149: =IFERROR(IF(P149="","",(P149-S149)/(1-S149)),"") | U149: =IF(P149="","Awaiting",IF(P149>=CVI_PASS,"PASS",IF(P149>=CVI_BORDER,"BORDERLINE","FAIL")))
A150: S001 | B150: Story Paragraph | C150: जादातर जनम कय रसम अउर नामकरन कय रसम कौने कौने समय पय होत है। | E150: The birth and naming ceremonies take place at specific auspicious times. | F150: Lifecycle | G150: Janam aur Naamkaran (¶1) | O150: =COUNTIF(H150:N150,">=3") | P150: =IF(COUNT(H150:N150)=0,"",COUNTIF(H150:N150,">=3")/COUNT(H150:N150)) | Q150: =IF(COUNT(H150:N150)=0,"",AVERAGE(H150:N150)) | R150: =IF(COUNT(H150:N150)<2,"",STDEV(H150:N150)) | S150: =IF(COUNT(H150:N150)=0,"",COMBIN(COUNT(H150:N150),COUNTIF(H150:N150,">=3"))*0.5^COUNT(H150:N150)) | T150: =IFERROR(IF(P150="","",(P150-S150)/(1-S150)),"") | U150: =IF(P150="","Awaiting",IF(P150>=CVI_PASS,"PASS",IF(P150>=CVI_BORDER,"BORDERLINE","FAIL")))
A151: S002 | B151: Story Paragraph | C151: जनम अउर नामकरन कय रसन पंडित द्वारा शुभ दिन अउर तिथि देख के निश्चित कीन जात है । | E151: The rituals are fixed by the priest after checking an auspicious day and date. | F151: Lifecycle | G151: Janam aur Naamkaran (¶2) | O151: =COUNTIF(H151:N151,">=3") | P151: =IF(COUNT(H151:N151)=0,"",COUNTIF(H151:N151,">=3")/COUNT(H151:N151)) | Q151: =IF(COUNT(H151:N151)=0,"",AVERAGE(H151:N151)) | R151: =IF(COUNT(H151:N151)<2,"",STDEV(H151:N151)) | S151: =IF(COUNT(H151:N151)=0,"",COMBIN(COUNT(H151:N151),COUNTIF(H151:N151,">=3"))*0.5^COUNT(H151:N151)) | T151: =IFERROR(IF(P151="","",(P151-S151)/(1-S151)),"") | U151: =IF(P151="","Awaiting",IF(P151>=CVI_PASS,"PASS",IF(P151>=CVI_BORDER,"BORDERLINE","FAIL")))
A152: S003 | B152: Story Paragraph | C152: नामकरन के रसम मा मामा,नाना-नानी ,बुआ-फ़ुफ़ा,चाची मौसी ,दादी ,नानी सब लॊग नामकरन के रसम मा जा थीं आवा थी । | E152: For the naming ceremony, the maternal uncle, grandparents, aunts, and grandmother all came. | F152: Lifecycle | G152: Janam aur Naamkaran (¶3) | O152: =COUNTIF(H152:N152,">=3") | P152: =IF(COUNT(H152:N152)=0,"",COUNTIF(H152:N152,">=3")/COUNT(H152:N152)) | Q152: =IF(COUNT(H152:N152)=0,"",AVERAGE(H152:N152)) | R152: =IF(COUNT(H152:N152)<2,"",STDEV(H152:N152)) | S152: =IF(COUNT(H152:N152)=0,"",COMBIN(COUNT(H152:N152),COUNTIF(H152:N152,">=3"))*0.5^COUNT(H152:N152)) | T152: =IFERROR(IF(P152="","",(P152-S152)/(1-S152)),"") | U152: =IF(P152="","Awaiting",IF(P152>=CVI_PASS,"PASS",IF(P152>=CVI_BORDER,"BORDERLINE","FAIL")))
A153: S004 | B153: Story Paragraph | C153: जनम अउर नामकरन के रसम मा फ़ूल-फ़ल ,केला ,पूडी,सब्जी सब लागत है । | E153: Flowers, fruits, bananas, puri, and vegetables are all part of the celebration. | F153: Lifecycle | G153: Janam aur Naamkaran (¶4) | O153: =COUNTIF(H153:N153,">=3") | P153: =IF(COUNT(H153:N153)=0,"",COUNTIF(H153:N153,">=3")/COUNT(H153:N153)) | Q153: =IF(COUNT(H153:N153)=0,"",AVERAGE(H153:N153)) | R153: =IF(COUNT(H153:N153)<2,"",STDEV(H153:N153)) | S153: =IF(COUNT(H153:N153)=0,"",COMBIN(COUNT(H153:N153),COUNTIF(H153:N153,">=3"))*0.5^COUNT(H153:N153)) | T153: =IFERROR(IF(P153="","",(P153-S153)/(1-S153)),"") | U153: =IF(P153="","Awaiting",IF(P153>=CVI_PASS,"PASS",IF(P153>=CVI_BORDER,"BORDERLINE","FAIL")))
A154: S005 | B154: Story Paragraph | C154: ज़नम अउर नामकरन कय विधि निकासन है । | E154: The ceremony of birth and naming is called 'Nikasan'. | F154: Lifecycle | G154: Janam aur Naamkaran (¶5) | O154: =COUNTIF(H154:N154,">=3") | P154: =IF(COUNT(H154:N154)=0,"",COUNTIF(H154:N154,">=3")/COUNT(H154:N154)) | Q154: =IF(COUNT(H154:N154)=0,"",AVERAGE(H154:N154)) | R154: =IF(COUNT(H154:N154)<2,"",STDEV(H154:N154)) | S154: =IF(COUNT(H154:N154)=0,"",COMBIN(COUNT(H154:N154),COUNTIF(H154:N154,">=3"))*0.5^COUNT(H154:N154)) | T154: =IFERROR(IF(P154="","",(P154-S154)/(1-S154)),"") | U154: =IF(P154="","Awaiting",IF(P154>=CVI_PASS,"PASS",IF(P154>=CVI_BORDER,"BORDERLINE","FAIL")))
A155: S006 | B155: Story Paragraph | C155: जनम अउर नामकरन के रसम का निकासन कहा थीं वोहमा भोज हुअत है भोज मा पूडी -सब्जी,हलुआ ,दही खीर आदि भोज लगता है । | E155: This ceremony is called Nikasan — a feast is held with puri-sabzi, halwa, yogurt, and kheer. | F155: Lifecycle | G155: Janam aur Naamkaran (¶6) | O155: =COUNTIF(H155:N155,">=3") | P155: =IF(COUNT(H155:N155)=0,"",COUNTIF(H155:N155,">=3")/COUNT(H155:N155)) | Q155: =IF(COUNT(H155:N155)=0,"",AVERAGE(H155:N155)) | R155: =IF(COUNT(H155:N155)<2,"",STDEV(H155:N155)) | S155: =IF(COUNT(H155:N155)=0,"",COMBIN(COUNT(H155:N155),COUNTIF(H155:N155,">=3"))*0.5^COUNT(H155:N155)) | T155: =IFERROR(IF(P155="","",(P155-S155)/(1-S155)),"") | U155: =IF(P155="","Awaiting",IF(P155>=CVI_PASS,"PASS",IF(P155>=CVI_BORDER,"BORDERLINE","FAIL")))
A156: S007 | B156: Story Paragraph | C156: जनम अउर नामकरन के समय व्यवस्था वोहकय महतारी-बाप ,घर वालेन करा थीं । | E156: All arrangements are made by the child's parents and family. | F156: Lifecycle | G156: Janam aur Naamkaran (¶7) | O156: =COUNTIF(H156:N156,">=3") | P156: =IF(COUNT(H156:N156)=0,"",COUNTIF(H156:N156,">=3")/COUNT(H156:N156)) | Q156: =IF(COUNT(H156:N156)=0,"",AVERAGE(H156:N156)) | R156: =IF(COUNT(H156:N156)<2,"",STDEV(H156:N156)) | S156: =IF(COUNT(H156:N156)=0,"",COMBIN(COUNT(H156:N156),COUNTIF(H156:N156,">=3"))*0.5^COUNT(H156:N156)) | T156: =IFERROR(IF(P156="","",(P156-S156)/(1-S156)),"") | U156: =IF(P156="","Awaiting",IF(P156>=CVI_PASS,"PASS",IF(P156>=CVI_BORDER,"BORDERLINE","FAIL")))
A157: S008 | B157: Story Vocab | C157: जनम | D157: Janam | E157: Birth | F157: Lifecycle | G157: Vocab from "Janam aur Naamkaran" | O157: =COUNTIF(H157:N157,">=3") | P157: =IF(COUNT(H157:N157)=0,"",COUNTIF(H157:N157,">=3")/COUNT(H157:N157)) | Q157: =IF(COUNT(H157:N157)=0,"",AVERAGE(H157:N157)) | R157: =IF(COUNT(H157:N157)<2,"",STDEV(H157:N157)) | S157: =IF(COUNT(H157:N157)=0,"",COMBIN(COUNT(H157:N157),COUNTIF(H157:N157,">=3"))*0.5^COUNT(H157:N157)) | T157: =IFERROR(IF(P157="","",(P157-S157)/(1-S157)),"") | U157: =IF(P157="","Awaiting",IF(P157>=CVI_PASS,"PASS",IF(P157>=CVI_BORDER,"BORDERLINE","FAIL")))
A158: S009 | B158: Story Vocab | C158: नामकरन | D158: Naamkaran | E158: Naming Ceremony | F158: Lifecycle | G158: Vocab from "Janam aur Naamkaran" | O158: =COUNTIF(H158:N158,">=3") | P158: =IF(COUNT(H158:N158)=0,"",COUNTIF(H158:N158,">=3")/COUNT(H158:N158)) | Q158: =IF(COUNT(H158:N158)=0,"",AVERAGE(H158:N158)) | R158: =IF(COUNT(H158:N158)<2,"",STDEV(H158:N158)) | S158: =IF(COUNT(H158:N158)=0,"",COMBIN(COUNT(H158:N158),COUNTIF(H158:N158,">=3"))*0.5^COUNT(H158:N158)) | T158: =IFERROR(IF(P158="","",(P158-S158)/(1-S158)),"") | U158: =IF(P158="","Awaiting",IF(P158>=CVI_PASS,"PASS",IF(P158>=CVI_BORDER,"BORDERLINE","FAIL")))
A159: S010 | B159: Story Vocab | C159: पंडित | D159: Pandit | E159: Priest | F159: Lifecycle | G159: Vocab from "Janam aur Naamkaran" | O159: =COUNTIF(H159:N159,">=3") | P159: =IF(COUNT(H159:N159)=0,"",COUNTIF(H159:N159,">=3")/COUNT(H159:N159)) | Q159: =IF(COUNT(H159:N159)=0,"",AVERAGE(H159:N159)) | R159: =IF(COUNT(H159:N159)<2,"",STDEV(H159:N159)) | S159: =IF(COUNT(H159:N159)=0,"",COMBIN(COUNT(H159:N159),COUNTIF(H159:N159,">=3"))*0.5^COUNT(H159:N159)) | T159: =IFERROR(IF(P159="","",(P159-S159)/(1-S159)),"") | U159: =IF(P159="","Awaiting",IF(P159>=CVI_PASS,"PASS",IF(P159>=CVI_BORDER,"BORDERLINE","FAIL")))
A160: S011 | B160: Story Vocab | C160: निकासन | D160: Nikasan | E160: Coming-out Ceremony | F160: Lifecycle | G160: Vocab from "Janam aur Naamkaran" | O160: =COUNTIF(H160:N160,">=3") | P160: =IF(COUNT(H160:N160)=0,"",COUNTIF(H160:N160,">=3")/COUNT(H160:N160)) | Q160: =IF(COUNT(H160:N160)=0,"",AVERAGE(H160:N160)) | R160: =IF(COUNT(H160:N160)<2,"",STDEV(H160:N160)) | S160: =IF(COUNT(H160:N160)=0,"",COMBIN(COUNT(H160:N160),COUNTIF(H160:N160,">=3"))*0.5^COUNT(H160:N160)) | T160: =IFERROR(IF(P160="","",(P160-S160)/(1-S160)),"") | U160: =IF(P160="","Awaiting",IF(P160>=CVI_PASS,"PASS",IF(P160>=CVI_BORDER,"BORDERLINE","FAIL")))
A161: S012 | B161: Story Vocab | C161: भोज | D161: Bhoj | E161: Feast | F161: Lifecycle | G161: Vocab from "Janam aur Naamkaran" | O161: =COUNTIF(H161:N161,">=3") | P161: =IF(COUNT(H161:N161)=0,"",COUNTIF(H161:N161,">=3")/COUNT(H161:N161)) | Q161: =IF(COUNT(H161:N161)=0,"",AVERAGE(H161:N161)) | R161: =IF(COUNT(H161:N161)<2,"",STDEV(H161:N161)) | S161: =IF(COUNT(H161:N161)=0,"",COMBIN(COUNT(H161:N161),COUNTIF(H161:N161,">=3"))*0.5^COUNT(H161:N161)) | T161: =IFERROR(IF(P161="","",(P161-S161)/(1-S161)),"") | U161: =IF(P161="","Awaiting",IF(P161>=CVI_PASS,"PASS",IF(P161>=CVI_BORDER,"BORDERLINE","FAIL")))
A162: S013 | B162: Story Paragraph | C162: हमरे समाज मा शादी से सम्बन्धित रसम लगन,तिलक ,विवाह होत है । | E162: In our society, wedding rituals include the engagement (Lagan), Tilak ceremony, and the marriage. | F162: Lifecycle | G162: Biaah ki Rasm (¶1) | O162: =COUNTIF(H162:N162,">=3") | P162: =IF(COUNT(H162:N162)=0,"",COUNTIF(H162:N162,">=3")/COUNT(H162:N162)) | Q162: =IF(COUNT(H162:N162)=0,"",AVERAGE(H162:N162)) | R162: =IF(COUNT(H162:N162)<2,"",STDEV(H162:N162)) | S162: =IF(COUNT(H162:N162)=0,"",COMBIN(COUNT(H162:N162),COUNTIF(H162:N162,">=3"))*0.5^COUNT(H162:N162)) | T162: =IFERROR(IF(P162="","",(P162-S162)/(1-S162)),"") | U162: =IF(P162="","Awaiting",IF(P162>=CVI_PASS,"PASS",IF(P162>=CVI_BORDER,"BORDERLINE","FAIL")))
...

Sheet Summary
A1: AwadhVaani — CVI Summary
A2: Headline metrics auto-compute as expert ratings are entered
A4: HEADLINE METRICS
A5: Total items in inventory | B5: =COUNTA('Items & Ratings'!A2:A196)
A6: Items with at least one rating | B6: =COUNT('Items & Ratings'!P2:P196)
A7: Items with no ratings yet | B7: =COUNTIF('Items & Ratings'!U2:U196,"Awaiting")
A9: S-CVI / Ave (target ≥ 0.90) | B9: =IFERROR(AVERAGE('Items & Ratings'!P2:P196),"—")
A10: S-CVI / UA (target ≥ 0.80) | B10: =IF(COUNT('Items & Ratings'!P2:P196)=0,"—",COUNTIF('Items & Ratings'!P2:P196,1)/COUNT('Items & Ratings'!P2:P196))
A11: Mean κ* across items | B11: =IFERROR(AVERAGE('Items & Ratings'!T2:T196),"—")
A13: Items PASS (I-CVI ≥ pass threshold) | B13: =COUNTIF('Items & Ratings'!U2:U196,"PASS")
A14: Items BORDERLINE | B14: =COUNTIF('Items & Ratings'!U2:U196,"BORDERLINE")
A15: Items FAIL | B15: =COUNTIF('Items & Ratings'!U2:U196,"FAIL")
A17: BREAKDOWN BY CONTENT TYPE
A18: Content Type | B18: Items | C18: S-CVI/Ave (this type) | D18: PASS
A19: Vocabulary | B19: =COUNTIF('Items & Ratings'!B2:B196,"Vocabulary") | C19: =IFERROR(AVERAGEIFS('Items & Ratings'!P2:P196,'Items & Ratings'!B2:B196,"Vocabulary"),"—") | D19: =COUNTIFS('Items & Ratings'!B2:B196,"Vocabulary",'Items & Ratings'!U2:U196,"PASS")
A20: Lesson Sentence | B20: =COUNTIF('Items & Ratings'!B2:B196,"Lesson Sentence") | C20: =IFERROR(AVERAGEIFS('Items & Ratings'!P2:P196,'Items & Ratings'!B2:B196,"Lesson Sentence"),"—") | D20: =COUNTIFS('Items & Ratings'!B2:B196,"Lesson Sentence",'Items & Ratings'!U2:U196,"PASS")
A21: Quiz Item | B21: =COUNTIF('Items & Ratings'!B2:B196,"Quiz Item") | C21: =IFERROR(AVERAGEIFS('Items & Ratings'!P2:P196,'Items & Ratings'!B2:B196,"Quiz Item"),"—") | D21: =COUNTIFS('Items & Ratings'!B2:B196,"Quiz Item",'Items & Ratings'!U2:U196,"PASS")
A22: Story Paragraph | B22: =COUNTIF('Items & Ratings'!B2:B196,"Story Paragraph") | C22: =IFERROR(AVERAGEIFS('Items & Ratings'!P2:P196,'Items & Ratings'!B2:B196,"Story Paragraph"),"—") | D22: =COUNTIFS('Items & Ratings'!B2:B196,"Story Paragraph",'Items & Ratings'!U2:U196,"PASS")
A23: Story Vocab | B23: =COUNTIF('Items & Ratings'!B2:B196,"Story Vocab") | C23: =IFERROR(AVERAGEIFS('Items & Ratings'!P2:P196,'Items & Ratings'!B2:B196,"Story Vocab"),"—") | D23: =COUNTIFS('Items & Ratings'!B2:B196,"Story Vocab",'Items & Ratings'!U2:U196,"PASS")
A26: INTERPRETATION REFERENCE
A27: S-CVI/Ave | B27: ≥ 0.90 — Excellent · 0.80–0.89 — Adequate · < 0.80 — Revise
A28: S-CVI/UA | B28: ≥ 0.80 — Strict universal-agreement target met
A29: Mean κ* | B29: > 0.74 Excellent · 0.60–0.74 Good · 0.40–0.59 Fair · < 0.40 Poor
A30: I-CVI item | B30: ≥ 0.78 (N=6–10) or ≥ 0.83 (N=3–5) — PASS

Sheet Expert Panel
A1: Expert ID | B1: Name | C1: Affiliation | D1: Background | E1: Years of Awadhi Experience | F1: Region / Sub-dialect Familiarity | G1: Email
A2: E1
A3: E2
A4: E3
A5: E4
A6: E5
A7: E6
A8: E7
A11: PARAMETERS
A12: Total experts (N) | B12: 7
A13: I-CVI pass threshold | B13: 0.78
A14: I-CVI borderline floor | B14: 0.6
